Workbook

Sheet Raw_Data
A1: user_id | B1: signup_date | C1: experiment_group | D1: region | E1: device_type | F1: traffic_source | G1: plan_type | H1: visited_landing_page | I1: started_trial | J1: completed_onboarding | K1: converted_to_paid | L1: revenue_30d | M1: support_tickets_30d | N1: refund_requested | O1: days_to_convert | P1: engagement_score
A2: USR-100001 | B2: 45732 | C2: Control | D2: North | E2: Desktop | F2: Email | G2: Basic | H2: 0 | I2: 0 | J2: 0 | K2: 0 | L2: 0 | M2: 0 | N2: 0 | P2: 45.7
A3: USR-100002 | B3: 45724 | C3: Control | D3: West | E3: Mobile | F3: Organic | G3: Free | H3: 1 | I3: 0 | J3: 0 | K3: 0 | L3: 0 | M3: 0 | N3: 0 | P3: 48.6
A4: USR-100003 | B4: 45771 | C4: Control | D4: East | E4: Mobile | F4: Paid Search | G4: Premium | H4: 1 | I4: 0 | J4: 0 | K4: 0 | L4: 0 | M4: 1 | N4: 0 | P4: 35.4
A5: USR-100004 | B5: 45781 | C5: Control | D5: South | E5: Mobile | F5: Email | G5: Basic | H5: 1 | I5: 0 | J5: 0 | K5: 0 | L5: 0 | M5: 0 | N5: 0 | P5: 64.6
A6: USR-100005 | B6: 45700 | C6: Control | D6: North | E6: Tablet | F6: Organic | G6: Free | H6: 0 | I6: 0 | J6: 0 | K6: 0 | L6: 0 | M6: 0 | N6: 0 | P6: 66.6
A7: USR-100006 | B7: 45685 | C7: Control | D7: East | E7: Mobile | F7: Organic | G7: Premium | H7: 1 | I7: 0 | J7: 0 | K7: 0 | L7: 0 | M7: 0 | N7: 0 | P7: 40.8
A8: USR-100007 | B8: 45755 | C8: Control | D8: East | E8: Mobile | F8: Paid Search | G8: Basic | H8: 1 | I8: 1 | J8: 0 | K8: 0 | L8: 0 | M8: 0 | N8: 0 | P8: 57.1
A9: USR-100008 | B9: 45794 | C9: Control | D9: South | E9: Mobile | F9: Paid Search | G9: Free | H9: 0 | I9: 0 | J9: 0 | K9: 0 | L9: 0 | M9: 0 | N9: 0 | P9: 36.4
A10: USR-100009 | B10: 45711 | C10: Control | D10: South | E10: Tablet | F10: Referral | G10: Basic | H10: 0 | I10: 0 | J10: 0 | K10: 0 | L10: 0 | M10: 0 | N10: 0 | P10: 55.4
A11: USR-100010 | B11: 45806 | C11: Control | D11: West | E11: Desktop | F11: Social | G11: Free | H11: 1 | I11: 0 | J11: 0 | K11: 0 | L11: 0 | M11: 0 | N11: 0 | P11: 57.3
A12: USR-100011 | B12: 45777 | C12: Control | D12: East | E12: Mobile | F12: Paid Search | G12: Basic | H12: 1 | I12: 1 | J12: 1 | K12: 0 | L12: 0 | M12: 0 | N12: 0 | P12: 63.6
A13: USR-100012 | B13: 45732 | C13: Control | D13: East | E13: Mobile | F13: Social | G13: Premium | H13: 1 | I13: 1 | J13: 1 | K13: 0 | L13: 0 | M13: 1 | N13: 0 | P13: 80.4
... A60: USR-100059 | B60: 45761 | C60: Control | D60: North | E60: Mobile | F60: Social | G60: Free | H60: 0 | I60: 0 | J60: 0 | K60: 0 | L60: 0 | M60: 2 | N60: 0 | P60: 48.9
A61: USR-100060 | B61: 45658 | C61: Control | D61: West | E61: Mobile | F61: Social | G61: Free | H61: 1 | I61: 1 | J61: 1 | K61: 1 | L61: 240.42 | M61: 0 | N61: 0 | O61: 16 | P61: 56.5
A62: USR-100061 | B62: 45749 | C62: Control | D62: South | E62: Mobile | F62: Referral | G62: Free | H62: 1 | I62: 0 | J62: 0 | K62: 0 | L62: 0 | M62: 0 | N62: 0 | P62: 53.7
A63: USR-100062 | B63: 45745 | C63: Control | D63: North | E63: Mobile | F63: Social | G63: Premium | H63: 0 | I63: 0 | J63: 0 | K63: 0 | L63: 0 | M63: 0 | N63: 0 | P63: 62.2
A64: USR-100063 | B64: 45792 | C64: Control | D64: South | E64: Desktop | F64: Organic | G64: Free | H64: 1 | I64: 0 | J64: 0 | K64: 0 | L64: 0 | M64: 0 | N64: 0 | P64: 50.2
A65: USR-100064 | B65: 45758 | C65: Control | D65: North | E65: Mobile | F65: Organic | G65: Basic | H65: 1 | I65: 0 | J65: 0 | K65: 0 | L65: 0 | M65: 0 | N65: 0 | P65: 74.3
A66: USR-100065 | B66: 45723 | C66: Control | D66: South | E66: Desktop | F66: Paid Search | G66: Free | H66: 1 | I66: 0 | J66: 0 | K66: 0 | L66: 0 | M66: 0 | N66: 0 | P66: 58
A67: USR-100066 | B67: 45807 | C67: Control | D67: South | E67: Mobile | F67: Organic | G67: Free | H67: 0 | I67: 0 | J67: 0 | K67: 0 | L67: 0 | M67: 0 | N67: 0 | P67: 46.7
A68: USR-100067 | B68: 45664 | C68: Control | D68: South | E68: Desktop | F68: Organic | G68: Premium | H68: 1 | I68: 0 | J68: 0 | K68: 0 | L68: 0 | M68: 1 | N68: 0 | P68: 49.6
A69: USR-100068 | B69: 45785 | C69: Control | D69: West | E69: Mobile | F69: Social | G69: Free | H69: 0 | I69: 0 | J69: 0 | K69: 0 | L69: 0 | M69: 0 | N69: 0 | P69: 60.4
A70: USR-100069 | B70: 45735 | C70: Control | D70: East | E70: Desktop | F70: Email | G70: Free | H70: 1 | I70: 1 | J70: 1 | K70: 0 | L70: 0 | M70: 0 | N70: 0 | P70: 55.3
A71: USR-100070 | B71: 45793 | C71: Control | D71: North | E71: Desktop | F71: Organic | G71: Free | H71: 0 | I71: 0 | J71: 0 | K71: 0 | L71: 0 | M71: 0 | N71: 0 | P71: 56.2
A72: USR-100071 | B72: 45724 | C72: Control | D72: West | E72: Mobile | F72: Email | G72: Free | H72: 0 | I72: 0 | J72: 0 | K72: 0 | L72: 0 | M72: 0 | N72: 0 | P72: 29.4
A73: USR-100072 | B73: 45724 | C73: Control | D73: East | E73: Mobile | F73: Email | G73: Free | H73: 1 | I73: 0 | J73: 0 | K73: 0 | L73: 0 | M73: 0 | N73: 0 | P73: 54.2
... A79: USR-100078 | B79: 45673 | C79: Control | D79: North | E79: Mobile | F79: Organic | G79: Free | H79: 0 | I79: 0 | J79: 0 | K79: 0 | L79: 0 | M79: 2 | N79: 0 | P79: 48.4
A80: USR-100079 | B80: 45708 | C80: Control | D80: West | E80: Desktop | F80: Organic | G80: Free | H80: 1 | I80: 1 | J80: 1 | K80: 1 | L80: 457.51 | M80: 0 | N80: 0 | O80: 7 | P80: 38
A81: USR-100080 | B81: 45798 | C81: Control | D81: East | E81: Mobile | F81: Social | G81: Free | H81: 1 | I81: 0 | J81: 0 | K81: 0 | L81: 0 | M81: 0 | N81: 0 | P81: 44.2
A82: USR-100081 | B82: 45785 | C82: Control | D82: South | E82: Mobile | F82: Organic | G82: Free | H82: 1 | I82: 1 | J82: 1 | K82: 0 | L82: 0 | M82: 0 | N82: 0 | P82: 81.2
A83: USR-100082 | B83: 45724 | C83: Control | D83: South | E83: Mobile | F83: Referral | G83: Free | H83: 1 | I83: 1 | J83: 0 | K83: 0 | L83: 0 | M83: 0 | N83: 0 | P83: 63.8
A84: USR-100083 | B84: 45748 | C84: Control | D84: South | E84: Desktop | F84: Email | G84: Free | H84: 0 | I84: 0 | J84: 0 | K84: 0 | L84: 0 | M84: 0 | N84: 0 | P84: 64.7
A85: USR-100084 | B85: 45719 | C85: Control | D85: West | E85: Mobile | F85: Social | G85: Basic | H85: 0 | I85: 0 | J85: 0 | K85: 0 | L85: 0 | M85: 0 | N85: 0 | P85: 60.4
A86: USR-100085 | B86: 45763 | C86: Control | D86: South | E86: Mobile | F86: Paid Search | G86: Free | H86: 0 | I86: 0 | J86: 0 | K86: 0 | L86: 0 | M86: 0 | N86: 0 | P86: 66.6
A87: USR-100086 | B87: 45666 | C87: Control | D87: North | E87: Desktop | F87: Organic | G87: Free | H87: 1 | I87: 0 | J87: 0 | K87: 0 | L87: 0 | M87: 0 | N87: 0 | P87: 50.9
A88: USR-100087 | B88: 45679 | C88: Control | D88: West | E88: Desktop | F88: Social | G88: Basic | H88: 0 | I88: 0 | J88: 0 | K88: 0 | L88: 0 | M88: 0 | N88: 0 | P88: 51
A89: USR-100088 | B89: 45777 | C89: Control | D89: South | E89: Mobile | F89: Email | G89: Premium | H89: 0 | I89: 0 | J89: 0 | K89: 0 | L89: 0 | M89: 0 | N89: 0 | P89: 65.8
A90: USR-100089 | B90: 45772 | C90: Control | D90: North | E90: Mobile | F90: Referral | G90: Basic | H90: 1 | I90: 0 | J90: 0 | K90: 0 | L90: 0 | M90: 0 | N90: 0 | P90: 61.8
A91: USR-100090 | B91: 45689 | C91: Control | D91: North | E91: Mobile | F91: Organic | G91: Basic | H91: 1 | I91: 0 | J91: 0 | K91: 0 | L91: 0 | M91: 0 | N91: 0 | P91: 54.5
...

Sheet Data_Quality_Check
A1: Column Name | B1: Missing Values | D1: User ID | E1: COUNT | J1: Duplicate User ID Check | K1: =COUNTA(Raw_Data!A1:A1408)-COUNTA(_xlfn.UNIQUE(Raw_Data!A1:A1408)) -> 7
A2: user_id | B2: =COUNTBLANK(Raw_Data!A2:A1409) -> 0 | E2: =COUNTIF(Raw_Data!A:A,Raw_Data!A2) -> 1 | G2: experiment_group | H2: Count of user_id
A3: signup_date | B3: =COUNTBLANK(Raw_Data!B2:B1409) -> 0 | E3: =COUNTIF(Raw_Data!A:A,Raw_Data!A3) -> 1 | G3: Control | H3: 693
A4: experiment_group | B4: =COUNTBLANK(Raw_Data!C2:C1409) -> 0 | E4: =COUNTIF(Raw_Data!A:A,Raw_Data!A4) -> 1 | G4: Treatment | H4: 715
A5: region | B5: =COUNTBLANK(Raw_Data!D2:D1409) -> 0 | E5: =COUNTIF(Raw_Data!A:A,Raw_Data!A5) -> 1 | G5: Grand Total | H5: 1408
A6: device_type | B6: =COUNTBLANK(Raw_Data!E2:E1409) -> 18 | E6: =COUNTIF(Raw_Data!A:A,Raw_Data!A6) -> 1
A7: traffic_source | B7: =COUNTBLANK(Raw_Data!F2:F1409) -> 24 | E7: =COUNTIF(Raw_Data!A:A,Raw_Data!A7) -> 1
A8: plan_type | B8: =COUNTBLANK(Raw_Data!G2:G1409) -> 0 | E8: =COUNTIF(Raw_Data!A:A,Raw_Data!A8) -> 1
A9: visited_landing_page | B9: =COUNTBLANK(Raw_Data!H2:H1409) -> 0 | E9: =COUNTIF(Raw_Data!A:A,Raw_Data!A9) -> 1
A10: started_trial | B10: =COUNTBLANK(Raw_Data!I2:I1409) -> 0 | E10: =COUNTIF(Raw_Data!A:A,Raw_Data!A10) -> 1
A11: completed_onboarding | B11: =COUNTBLANK(Raw_Data!J2:J1409) -> 0 | E11: =COUNTIF(Raw_Data!A:A,Raw_Data!A11) -> 1
A12: converted_to_paid | B12: =COUNTBLANK(Raw_Data!K2:K1409) -> 0 | E12: =COUNTIF(Raw_Data!A:A,Raw_Data!A12) -> 1
A13: revenue_30d | B13: =COUNTBLANK(Raw_Data!L2:L1409) -> 0 | E13: =COUNTIF(Raw_Data!A:A,Raw_Data!A13) -> 1
A14: support_tickets_30d | B14: =COUNTBLANK(Raw_Data!M2:M1409) -> 0 | E14: =COUNTIF(Raw_Data!A:A,Raw_Data!A14) -> 1
A15: refund_requested | B15: =COUNTBLANK(Raw_Data!N2:N1409) -> 0 | E15: =COUNTIF(Raw_Data!A:A,Raw_Data!A15) -> 1
A16: days_to_convert | B16: =COUNTBLANK(Raw_Data!O2:O1409) -> 1336 | E16: =COUNTIF(Raw_Data!A:A,Raw_Data!A16) -> 1
A17: engagement_score | B17: =COUNTBLANK(Raw_Data!P2:P1409) -> 14 | E17: =COUNTIF(Raw_Data!A:A,Raw_Data!A17) -> 1
E18: =COUNTIF(Raw_Data!A:A,Raw_Data!A18) -> 1
E19: =COUNTIF(Raw_Data!A:A,Raw_Data!A19) -> 1
E20: =COUNTIF(Raw_Data!A:A,Raw_Data!A20) -> 1
E21: =COUNTIF(Raw_Data!A:A,Raw_Data!A21) -> 1
E22: =COUNTIF(Raw_Data!A:A,Raw_Data!A22) -> 1
E23: =COUNTIF(Raw_Data!A:A,Raw_Data!A23) -> 1
E24: =COUNTIF(Raw_Data!A:A,Raw_Data!A24) -> 1
E25: =COUNTIF(Raw_Data!A:A,Raw_Data!A25) -> 1
E26: =COUNTIF(Raw_Data!A:A,Raw_Data!A26) -> 1
E27: =COUNTIF(Raw_Data!A:A,Raw_Data!A27) -> 1
E28: =COUNTIF(Raw_Data!A:A,Raw_Data!A28) -> 1
E29: =COUNTIF(Raw_Data!A:A,Raw_Data!A29) -> 1
... E1409: =COUNTIF(Raw_Data!A:A,Raw_Data!A1409) -> 2

Sheet Summary_Metrics
A1: Metric | B1: Control | C1: Treatment
A2: User Count | B2: =COUNTIF(Raw_Data!C:C,"Control") -> 693 | C2: =COUNTIF(Raw_Data!C:C,"Treatment") -> 715
A3: Landing Page Visit Rate | B3: =COUNTIFS(Raw_Data!C:C,"Control",Raw_Data!H:H,1)/COUNTIF(Raw_Data!C:C,"Control") -> 0.63636364 | C3: =COUNTIFS(Raw_Data!C:C,"Treatment",Raw_Data!H:H,1)/COUNTIF(Raw_Data!C:C,"Treatment") -> 0.72587413
A4: Trial Start Rate | B4: =COUNTIFS(Raw_Data!C:C,"Control",Raw_Data!I:I,1)/COUNTIF(Raw_Data!C:C,"Control") -> 0.25108225 | C4: =COUNTIFS(Raw_Data!C:C,"Treatment",Raw_Data!I:I,1)/COUNTIF(Raw_Data!C:C,"Treatment") -> 0.29090909
A5: Onboarding Completion Rate | B5: =COUNTIFS(Raw_Data!C:C,"Control",Raw_Data!J:J,1)/COUNTIF(Raw_Data!C:C,"Control") -> 0.15584416 | C5: =COUNTIFS(Raw_Data!C:C,"Treatment",Raw_Data!J:J,1)/COUNTIF(Raw_Data!C:C,"Treatment") -> 0.21258741
A6: Paid Conversion Rate | B6: =COUNTIFS(Raw_Data!C:C,"Control",Raw_Data!K:K,1)/COUNTIF(Raw_Data!C:C,"Control") -> 0.031746032 | C6: =COUNTIFS(Raw_Data!C:C,"Treatment",Raw_Data!K:K,1)/COUNTIF(Raw_Data!C:C,"Treatment") -> 0.06993007
A7: Average Revenue Per User | B7: =SUMIFS(Raw_Data!L:L,Raw_Data!C:C,"Control")/COUNTIF(Raw_Data!C:C,"Control") -> 51.749322 | C7: =SUMIFS(Raw_Data!L:L,Raw_Data!C:C,"Treatment")/COUNTIF(Raw_Data!C:C,"Treatment") -> 53.875119
A8: Average Revenue Per Converted User | B8: =SUMIFS(Raw_Data!L:L,Raw_Data!C:C,"Control")/COUNTIFS(Raw_Data!C:C,"Control",Raw_Data!K:K,1) -> 1630.1036 | C8: =SUMIFS(Raw_Data!L:L,Raw_Data!C:C,"Treatment")/COUNTIFS(Raw_Data!C:C,"Treatment",Raw_Data!K:K,1) -> 770.4142
A9: Refund Rate | B9: =COUNTIFS(Raw_Data!C:C,"Control",Raw_Data!N:N,1)/COUNTIF(Raw_Data!C:C,"Control") -> 0 | C9: =COUNTIFS(Raw_Data!C:C,"Treatment",Raw_Data!N:N,1)/COUNTIF(Raw_Data!C:C,"Treatment") -> 0.0041958042
A10: Support Ticket Rate | B10: =AVERAGEIFS(Raw_Data!M:M,Raw_Data!C:C,"Control") -> 0.21933622 | C10: =AVERAGEIFS(Raw_Data!M:M,Raw_Data!C:C,"Treatment") -> 0.37202797
A11: Average Engagement Score | B11: =AVERAGEIFS(Raw_Data!P:P,Raw_Data!C:C,"Control") -> 57.026201 | C11: =AVERAGEIFS(Raw_Data!P:P,Raw_Data!C:C,"Treatment") -> 62.931966
A12: Average Days To Convert | B12: =AVERAGEIFS(Raw_Data!O:O,Raw_Data!C:C,"Control",Raw_Data!K:K,1) -> 8.8636364 | C12: =AVERAGEIFS(Raw_Data!O:O,Raw_Data!C:C,"Treatment",Raw_Data!K:K,1) -> 6.4
A13: Support Ticket Rate | B13: =COUNTIFS(Raw_Data!C:C,"Control",Raw_Data!M:M,">0")/COUNTIF(Raw_Data!C:C,"Control") -> 0.14718615 | C13: =COUNTIFS(Raw_Data!C:C,"Treatment",Raw_Data!M:M,">0")/COUNTIF(Raw_Data!C:C,"Treatment") -> 0.24755245

Sheet Segment_Analysis
A1: Sum of converted_to_paid | B1: experiment_group
A2: region | B2: Control | C2: Treatment | D2: Grand Total
A3: East | B3: 0.26666667 | C3: 0.73333333 | D3: 1
A4: North | B4: 0.30434783 | C4: 0.69565217 | D4: 1
A5: South | B5: 0.3 | C5: 0.7 | D5: 1
A6: West | B6: 0.35714286 | C6: 0.64285714 | D6: 1
A7: Grand Total | B7: 0.30555556 | C7: 0.69444444 | D7: 1
A11: Sum of converted_to_paid | B11: experiment_group
A12: device_type | B12: Control | C12: Treatment | D12: Grand Total
A13: Desktop | B13: 0.39130435 | C13: 0.60869565 | D13: 1
A14: Mobile | B14: 0.25581395 | C14: 0.74418605 | D14: 1
A15: Tablet | B15: 0.2 | C15: 0.8 | D15: 1
A16: (blank) | B16: 1 | C16: 0 | D16: 1
A17: Grand Total | B17: 0.30555556 | C17: 0.69444444 | D17: 1
A21: Sum of converted_to_paid | B21: experiment_group
A22: traffic_source | B22: Control | C22: Treatment | D22: Grand Total
A23: Email | B23: 0.33333333 | C23: 0.66666667 | D23: 1
A24: Organic | B24: 0.25 | C24: 0.75 | D24: 1
A25: Paid Search | B25: 0.15384615 | C25: 0.84615385 | D25: 1
A26: Referral | B26: 0.16666667 | C26: 0.83333333 | D26: 1
A27: Social | B27: 0.55555556 | C27: 0.44444444 | D27: 1
A28: (blank) | B28: 0.33333333 | C28: 0.66666667 | D28: 1
A29: Grand Total | B29: 0.30555556 | C29: 0.69444444 | D29: 1

Sheet Hypothesis_Test
A1: t-Test: Paired Two Sample for Means
B3: 693 | C3: 715
A4: Mean | B4: 159.01676 | C4: 81.413124
A5: Variance | B5: 238509.73 | C5: 52753.376
A6: Observations | B6: 11 | C6: 11
A7: Pearson Correlation | B7: 0.99837643
A8: Hypothesized Mean Difference | B8: 0
A9: df | B9: 10
A10: t Stat | B10: 0.99223412
A11: P(T<=t) one-tail | B11: 0.17224248
A12: t Critical one-tail | B12: 1.8124611
A13: P(T<=t) two-tail | B13: 0.34448496
A14: t Critical two-tail | B14: 2.2281389
